Workbook
Name act_gulf: Assumptions!$B$56
Name act_india: Assumptions!$B$57
Name act_referral: Assumptions!$B$55
Name act_s0: Assumptions!$B$49
Name act_s1a: Assumptions!$B$47
Name act_s1b: Assumptions!$B$48
Name act_s2: Assumptions!$B$51
Name act_s3: Assumptions!$B$50
Name act_s4: Assumptions!$B$52
Name act_s5: Assumptions!$B$53
Name act_s6: Assumptions!$B$54
Name aed_usd: Assumptions!$B$7
Name agent_commission: 'Scenario Parameters'!$B$113
Name agent_productivity: 'Scenario Parameters'!$B$17
Name agents_gulf_y1: Assumptions!$B$100
Name agents_gulf_y2: Assumptions!$B$101
Name agents_gulf_y3: Assumptions!$B$102
Name agents_gulf_y4: Assumptions!$B$103
Name agents_gulf_y5: Assumptions!$B$104
Name agents_gulf_y6: Assumptions!$B$105
Name agents_gulf_y7: Assumptions!$B$106
Name agents_india_y1: Assumptions!$B$107
Name agents_india_y2: Assumptions!$B$108
Name agents_india_y3: Assumptions!$B$109
Name agents_india_y4: Assumptions!$B$110
Name agents_india_y5: Assumptions!$B$111
Name agents_india_y6: Assumptions!$B$112
Name agents_india_y7: Assumptions!$B$113
Name agents_uae_y1: Assumptions!$B$93
Name agents_uae_y2: Assumptions!$B$94
Name agents_uae_y3: Assumptions!$B$95
Name agents_uae_y4: Assumptions!$B$96
Name agents_uae_y5: Assumptions!$B$97
Name agents_uae_y6: Assumptions!$B$98
Name agents_uae_y7: Assumptions!$B$99
Name atm_a1500: 'Scenario Parameters'!$B$55
Name atm_a3000: 'Scenario Parameters'!$B$56
Name atm_a3000p: 'Scenario Parameters'!$B$57
Name atm_a500: 'Scenario Parameters'!$B$54
Name atm_allowance: Assumptions!$B$18
Name atm_fee: Assumptions!$B$19
Name atmm_a1500: 'Scenario Parameters'!$B$59
Name atmm_a3000: 'Scenario Parameters'!$B$60
Name atmm_a3000p: 'Scenario Parameters'!$B$61
Name atmm_a500: 'Scenario Parameters'!$B$58
Name audit_usd: 'Scenario Parameters'!$B$106
Name aum_per_partner: 'Scenario Parameters'!$B$83
Name aum_per_partner_user: 'Scenario Parameters'!$B$82
Name b2b_fee: 'Scenario Parameters'!$B$79
Name bar_grams: Assumptions!$B$10
Name benef_count: 'Scenario Parameters'!$B$70
Name benef_fee: Assumptions!$B$26
Name cac7_gulf: 'Scenario Parameters'!$B$22
Name cac7_india: 'Scenario Parameters'!$B$23
Name cac7_uae: 'Scenario Parameters'!$B$21
Name cac_gulf: 'Scenario Parameters'!$B$19
Name cac_india: 'Scenario Parameters'!$B$20
Name cac_uae: 'Scenario Parameters'!$B$18
Name card_activation: 'Scenario Parameters'!$B$49
Name card_fixed_usd: 'Scenario Parameters'!$B$115

Sheet Cover
B2: Aurumix Revenue Model
B3: Hybrid Monthly + Annual View | 7-Year Projection
B5: Date | C5: =TODAY()
B6: Scope | C6: Six revenue streams at their full charge, with the fabrication premium as cost of goods sold, plus the modelled cost base, net profit, unit economics, regulatory capital, the float and the peak funding need. Headcount and tax are not yet in the cost base, so every profit figure is an upper bound.
B7: Periods | C7: 24 monthly (M1-M24) + 5 annual (Y3-Y7) = 29 total. M1 = January 2027
B8: Engine | C8: Rolling customer balance: opening + new - churned = closing, by region. Customers who stop paying keep their gold and move to a HOLDERS balance.
B9: Metal | C9: 100 g bars throughout. One entry fee, one fabrication premium.
B10: Prepared by | C10: Tokenomics.net: Custom Data Room Engagement
B12: COLOR LEGEND
B13: BLUE text | C13: Hardcoded inputs (Assumptions & Scenario Parameters)
B14: BLACK text | C14: In-sheet formulas
B15: GREEN text | C15: Cross-sheet references
B17: SHEETS
B18: Cover: This page
B19: Assumptions: Fixed inputs, activation calendar, seasonality, market ceilings
B20: Scenario Parameters: Base / Aggressive / Conservative, plus structural switches
B21: Model: Customer engine, AUM and the six revenue streams (29 periods)
B22: Summary: Annual revenue by stream (Y1-Y7), revenue mix, key metrics
B24: SIMPLIFIED BUILD - cohort and archetype detail moves to the Phase 5 simulation.
B25: Kept as inputs rather than engines: the holders balance, the fabrication premium inside stream 1, and the ICS qualification rate (a memo that prices benefits; it no longer gates the card).

Sheet Assumptions
A1: =Cover!$B$2
A2: Inputs and Assumptions
A4: PRICING AND METAL
A5: Parameter | B5: Value | C5: Unit | D5: Source
A6: Gold price at M1 | B6: 141.46 | C6: USD/g | D6: USD 4,400/oz verified 2026-08-17. THE STARTING PRICE - it no longer holds for the whole horizon; see the appreciation rate below and the live 'Gold price (this period)' row on the Model. CITED.
A7: AED/USD peg | B7: 3.6725 | C7: AED/USD | D7: CBUAE peg. CITED.
A8: Entry fee charged | B8: 0.05 | C8: % of contribution | D8: Decision 9, client-stated. A SINGLE RATE throughout. CLIENT INPUT.
A9: Fabrication premium paid | B9: 0.015 | C9: % over spot | D9: 100 g bars. OBSERVED (D28): goldtrade.ae 19 Aug 2026 measured 100 g at +1.71% (PAMP 1.75, Valcambi 1.67), less the published 25 bp bulk gradient. THE ENTRY FEE IS A MARGIN, NOT A FEE - this is netted off stream 1, because it is cost OF REVENUE. Reporting stream 1 gross would read ~43% high.
A10: Bar denomination | B10: 100 | C10: grams | D10: 100 g throughout, by agreement. OBSERVED.
A12: CARD ECONOMICS
A13: Parameter | B13: Value | C13: Unit | D13: Source
A14: Interchange - Gold | B14: 0.018 | C14: % of spend | D14: Visa UAE IRF schedule, 18 Oct 2025. CITED, PRIMARY. The live model reads the FLAT GOLD RATE: replacing the full 1.80/2.05/2.10 ladder with it moves stream 2 by only ~2% of gross profit at Y7, because Sovereign is 1.2% of tiered accounts.
A15: Per-transaction processor fee | B15: 0.1 | C15: USD/authorised txn | D15: WHAT THE PROCESSOR CHARGES AURUMIX to authorise and switch each transaction - NOT passed to the cardholder, and it cannot be: no consumer card charges per swipe on normal purchases, the card here is a REWARD for saving rather than a product sold, and a declined authorisation cannot be billed to anyone. Issuing economics are structurally: earn interchange, pay scheme and processing costs out of it. USD 0.10 is Stripe Issuing's PUBLISHED RACK RATE, used as a proxy because NO UAE PROCESSOR PUBLISHES PRICING. At volume, processors commonly reach USD 0.02-0.05 - a term-sheet negotiation, and at USD 0.03 the minimum profitable transaction falls from ~AED 77 to ~AED 23. CITED as a proxy.
A16: Decline uplift on authorised txns | B16: 0.06 | C16: % uplift | D16: The processor fee is charged per AUTHORISATION, not per settled transaction, so declined attempts are billable to Aurumix and chargeable to nobody. ASSUMPTION.
A17: FX margin on foreign spend | B17: 0.02 | C17: % of foreign spend | D17: Market rate ~2%, converged across four comparables. CITED.
A18: Free ATM allowance (Gold) | B18: 1000 | C18: AED/month | D18: Monthly and NOT rolling. Set deliberately ABOVE the median draw - that is the finding. CITED.
A19: ATM fee over the allowance | B19: 0.02 | C19: % of the excess | D19: Sector converged. CITED.
A20: Card issuance fee | B20: 75 | C20: AED one-off | D20: Charged at base level, waived at upper tiers. CITED structure, ASSUMPTION rate.
A21: Card replacement fee | B21: 100 | C21: AED per event | D21: Market-normal UAE replacement is AED 75-150. ASSUMPTION.
A23: OTHER STREAM PRICING
A24: Parameter | B24: Value | C24: Unit | D24: Source
A25: Family plan / Digital Will price | B25: 50 | C25: USD/yr | D25: RE-PRICED 2026-08-21 from USD 120/yr. THE OLD PRICE WAS ABOVE TRUST & WILL'S PREMIUM US MEMBERSHIP (USD 49/yr) AND WAS 33% OF EVERYTHING THE CUSTOMER SAVES IN A YEAR - a USD 30/month saver puts away USD 360, and we were charging 120 of it. THE INDUSTRY MODEL IS A ONE-OFF FEE PLUS A SMALL ANNUAL UPDATE LAYER, and it is the annual layer this row represents: Trust & Will USD 199 one-off + USD 49/yr; Farewill GBP 100 + GBP 10/yr; Epilogue C$139 with NO subscription at all; other platforms renew updates at ~C$4.50/yr. Formal UAE will registration is a different product entirely and one-off - DIFC AED 10,000 single / 15,000 mirror, Abu Dhabi Civil Court AED 950 as the cheapest formal route. Indian online wills run INR 500-4,000 basic. Family add-ons on finance apps are usually BUNDLED FREE; where charged it is USD 5-15/month for a WHOLE HOUSEHOLD (Monarch 99.99/yr, Zeta 59.99/yr, Greenlight 5.99/mo). SET AT USD 50/yr, client instruction 2026-08-21. That is essentially TRUST & WILL'S USD 49/yr MEMBERSHIP - a defensible anchor in that it matches the best-known product in the category, but NOTE WHOSE PRODUCT IT IS: Trust & Will sells to US customers who paid 199-599 up front for an estate plan, not to a migrant worker saving USD 30 a month. At 50 the plan is 14% OF EVERYTHING THE CUSTOMER SAVES IN A YEAR, against 10% at 36 and 33% at the original 120. It is no longer absurd, but it is priced at a developed-market benchmark for an emerging-market customer, and that is the line an adviser would push on. A ONE-OFF SETUP FEE IS NOT MODELLED - if the client wants the full industry structure, that is a second row, not a bigger number here. CITED comparators, ASSUMPTION on the point in the range.
A26: Additional beneficiary fee | B26: 6 | C26: USD/yr each | D26: ADDED 2026-08-21, client instruction. Charged per named beneficiary BEYOND THE FIRST, which the plan includes - the standard shape for this kind of add-on, and the reason the formula carries a MAX(0, n-1) rather than charging every beneficiary. NO COMPARABLE EXISTS: will services price PER WILL, not per beneficiary. DIFC charges more for a MIRROR will (two people) and more again for guardianship, but nobody publishes a per-beneficiary tariff. So this is priced on COST RECOVERY, which is the defensible basis available: every named beneficiary needs identity capture and AML screening, and Sumsub screening already sits in this model at ~USD 1.85 per check in the redemption cost memo. USD 6/yr covers that with margin without becoming a second subscription. DELIBERATELY SMALL. At 1.5 chargeable beneficiaries it adds USD 9/yr to a USD 50 plan - an 18% uplift on a stream worth ~3.5% of revenue, so it cannot move the model and should not be tuned to try. ASSUMPTION on a cost-recovery basis.
A27: Credit origination fee - gross | B27: 0.01 | C27: % of draw | D27: Finance House UAE gold loan Key Facts Statement carries a 1% processing fee - the one gross rate with a real UAE anchor. CITED.
A28: Credit origination - Aurumix share | B28: 0.5 | C28: % of gross | D28: ASSUMPTION.
A29: Credit servicing fee - gross | B29: 0.005 | C29: %/yr of drawn | D29: ASSUMPTION.
A30: Credit servicing - Aurumix share | B30: 0.7 | C30: % of gross | D30: The highest of the heads: servicing is where Aurumix does the actual work. ASSUMPTION.
A31: LTV against collateral | B31: 0.5 | C31: % of collateral | D31: _draft_ics-scoring.md sec 6.2, settled 2026-08-13. CITED.
A32: Spot ticket - UAE | B32: 190 | C32: USD/purchase | D32: OBSERVED, PRIMARY. Botim gold: average ticket AED 700, Khaleej Times, Nov 2025 (= USD 191 at the peg). CROSS-CHECKS against the same platform's own volume disclosure - AED 100m over 128,000 trades implies AED 781. THE STRONGEST COMPARABLE IN THIS MODEL: Botim is a messaging app that became the default for Gulf expats and added gold in Aug 2025, so its users ARE Aurumix's customers - same country, same segment, same product, same period. Note 64% of its users buy under AED 500, so the mean sits above the median and this figure is, if anything, generous.
A33: Spot ticket - Oman and Bahrain | B33: 145 | C33: USD/purchase | D33: INFERRED - THE WEAKEST OF THE THREE. No GCC platform outside the UAE publishes an average ticket; this is a CONFIRMED NEGATIVE, not a gap in the search. Taken as the UAE figure scaled by the regional income gap (SIP 26.00/33.60 = 0.77x). Do not present this as sourced.
A34: Spot ticket - India | B34: 40 | C34: USD/purchase | D34: OBSERVED, PROXY. Augmont: average festive-season purchase Rs 3,300, Times of India, Sep 2025 (= ~USD 38). Augmont is a licensed refiner and digital gold platform; a festive lump is structurally the same act as a spot purchase, which is why it is preferred to the alternatives. REJECTED: SafeGold Rs 5,000-8,000 (May 2026) - that book skews to investors, while Aurumix's Indian customer saves USD 30 a month; MMTC-PAMP Rs 800-1,200 - closer to routine micro-saving than a lump; Rs 230 industry-wide - a LinkedIn aggregate, not a citable source. WEAKER THAN THE UAE FIGURE: right country and right behaviour, but Aurumix's Indian customer is poorer than Augmont's average buyer, so 40 may be generous.
A35: Spot attach rate - UAE | B35: 0.12 | C35: % of customers/yr | D35: Share of paying customers who make ANY spot purchase in a year - NOT a monthly rate, and NOT how often a buyer buys (that is the separate frequency input). Set on the affordability ratio above: the spot ticket as a multiple of the same customer's monthly SIP. NO PUBLISHED BENCHMARK EXISTS - confirmed negative. KNOWN SIMPLIFICATION: v2.6 applied a TENURE UPLIFT here ('a 3-year account is ~2x as likely to buy spot as a 6-month account') which v3.0 dropped, so this is flat from day one and OVERSTATES SPOT IN THE EARLY YEARS, when nearly every account is young. Restore the uplift in the Phase 5 simulation. ASSUMPTION, structured on an observable driver.
A36: Spot attach rate - Oman and Bahrain | B36: 0.1 | C36: % of customers/yr | D36: Share of paying customers who make ANY spot purchase in a year - NOT a monthly rate, and NOT how often a buyer buys (that is the separate frequency input). Set on the affordability ratio above: the spot ticket as a multiple of the same customer's monthly SIP. NO PUBLISHED BENCHMARK EXISTS - confirmed negative. KNOWN SIMPLIFICATION: v2.6 applied a TENURE UPLIFT here ('a 3-year account is ~2x as likely to buy spot as a 6-month account') which v3.0 dropped, so this is flat from day one and OVERSTATES SPOT IN THE EARLY YEARS, when nearly every account is young. Restore the uplift in the Phase 5 simulation. ASSUMPTION, structured on an observable driver.
A37: Spot attach rate - India | B37: 0.35 | C37: % of customers/yr | D37: Share of paying customers who make ANY spot purchase in a year - NOT a monthly rate, and NOT how often a buyer buys (that is the separate frequency input). Set on the affordability ratio above: the spot ticket as a multiple of the same customer's monthly SIP. NO PUBLISHED BENCHMARK EXISTS - confirmed negative. KNOWN SIMPLIFICATION: v2.6 applied a TENURE UPLIFT here ('a 3-year account is ~2x as likely to buy spot as a 6-month account') which v3.0 dropped, so this is flat from day one and OVERSTATES SPOT IN THE EARLY YEARS, when nearly every account is young. Restore the uplift in the Phase 5 simulation. ASSUMPTION, structured on an observable driver.
A39: SIP RULES
A40: Parameter | B40: Value | C40: Unit | D40: Source
A41: SIP hard floor | B41: 20 | C41: USD/month | D41: Rejected outright below; never partially credited. CITED.
A42: Confirmed SIP gate | B42: 6 | C42: consecutive payments | D42: Client's own figure. The gate is why eligibility is NOT universal - see the two eligibility parameters on the Scenario sheet. CLIENT INPUT.
A43: Cost per redemption event | B43: 1.85 | C43: USD | D43: CUT TWICE, AND BOTH CUTS WERE DELIBERATE. From 4.20 to 3.20 on 2026-08-20, removing the outbound bank transfer fee (USD 1.00-2.50) as the customer's cost to bear. From 3.20 to 1.85 on 2026-08-26, client instruction, removing the ~1.35 of operational handling. WHAT REMAINS IS SUMSUB AML RE-SCREENING AT 1.85, the same published per-verification rate the onboarding line uses - a redemption triggers a re-screen. NOT a double count with the KYC line: that one charges new customers at onboarding, this one charges a different event. WHAT WAS REMOVED IS NOT ZERO. Operational handling - the staff time to check, approve and settle a redemption - is real work; it is now assumed to sit inside headcount rather than being priced per event. WHEN HEADCOUNT LANDS, CONFIRM IT IS ACTUALLY CARRIED THERE, or this cost has quietly vanished from the model rather than moved. NOT IN THE REVENUE MODEL: redemption is a COST and arrives with the cost build. This row is carried so the driver is documented and the unit rate already agreed. THE FINDING IT CARRIES IS UNCHANGED AND IS THE POINT - VARA Annex 2 III.E.4 forbids charging ANY fee on redemption, verified verbatim at primary source, so the cost is 100% absorbed, no offsetting revenue exists or can exist, and THERE CAN NEVER BE AN EXIT FEE. DERIVED.
A45: ACTIVATION CALENDAR - the single source of every activation period
...

Sheet Scenario Parameters
A1: =Cover!$B$2
A2: Scenario Parameters
A4: SCENARIO SELECTOR
A6: Select Scenario: | B6: Base | C6: =IF($B$6="Base",1,IF($B$6="Aggressive",2,3)) | D6: <- index | G6: One switch, three columns. Every parameter below resolves through it.
A8: GROUP A0: THE METAL
A9: Parameter | B9: Active Value | C9: Base | D9: Aggressive | E9: Conservative | F9: Unit
A10: Gold price appreciation | B10: =CHOOSE($C$6,C10,D10,E10) | C10: 0.081 | D10: 0.12 | E10: 0 | F10: %/yr | G10: ADDED 2026-08-21, client instruction, replacing a flat price. 8.1% is the COMPOUND ANNUAL GROWTH RATE SINCE 1971, the end of the gold standard - chosen because it is the LONGEST window and therefore the least cherry-picked. The shorter the window the better gold looks: ~8.6% over 50 years, ~9-10% over 20, ~13-14% over 10, and over 20% over the last 5. Taking the recent decade would have flattered the model on a rally. CITED. THIS IS A NOMINAL RATE AND NOTHING ELSE IN THE MODEL INFLATES. SIP tickets, spot tickets, CAC, card fees and the B2B fee are all frozen in 2027 dollars. There is NO CONSENSUS POSITIVE LONG-RUN REAL RETURN for gold - it is generally treated as a store of value with a near-zero real yield - so most of this 8.1% IS INFLATION. Applying it to the metal while freezing everything else quietly asserts that gold outruns wages, prices and costs by 8% a year for seven years, which is not a claim anyone would defend out loud. The Model therefore also carries AUM AT THE CONSTANT M1 PRICE, and that is the honest series for judging whether the BUSINESS grew. Conservative is set at 0.0% deliberately: it restores the original flat-price design, under which every revenue change is attributable to the business rather than the metal.
A11: Float buffer - days of demand held | B11: =CHOOSE($C$6,C11,D11,E11) | C11: 10 | D11: 6 | E11: 20 | F11: days | G11: S50, the SOFT HALF of the float sizing rule. The corpus states the rule as 'one bar denomination plus a buffer of N days trailing inflow' and NEVER SETS N. WHAT THE BUFFER IS FOR: how long it takes to get REPLACEMENT metal into the vault - dealer lead time, weekend and holiday gaps, payment clearing, and the days a dealer cannot fill 100 g. It is a REPLENISHMENT question. NOT the fill window, which is how long demand takes to CONSUME a bar. The brief anchors the 10 days on the fill window and that is the wrong anchor - how fast the shelf empties and how fast it can be restocked are different questions that only happen to give a similar answer at launch. Corrected here 2026-08-26; the brief still carries the old reasoning. 10 days is a working number for a dealer who has not been chosen yet, and it is DEALER-DEPENDENT: a T+2 commitment would cut the float by roughly two-thirds. IT CHANGES NOTHING AT LAUNCH. Below 10 grams a day - which is about month six - the two-bar floor is larger, so M1 is USD 28,716 for ANY buffer from 0 to 49 days. It binds only at scale, where it is worth USD 64,669 per day of buffer by Y7 and USD 905k between the Aggressive and Conservative settings. ASSUMPTION, and the one to flex: the only number in the float calculation that was neither observed nor settled in the design docs.
A13: GROUP A: CUSTOMERS AND CHURN
A14: Parameter | B14: Active Value | C14: Base | D14: Aggressive | E14: Conservative | F14: Unit
A15: Persistency - customers still paying after 12 months | B15: =CHOOSE($C$6,C15,D15,E15) | C15: 0.55 | D15: 0.65 | E15: 0.45 | F15: % | G15: THE HEADLINE RETENTION NUMBER, and the one a client can argue with. Everything about churn is derived from it. Governs lifetime value, referral economics and agent commission at once. DERIVED from the archetype work: the simulation can refine it, but 55% is what that engine produced.
A16: Monthly churn rate (derived) | B16: =1-'Scenario Parameters'!$B$15^(1/12) | F16: %/month | G16: DERIVED, not typed: the monthly rate that reproduces the persistency above over twelve months. Change persistency and this follows. Base 55% implies ~4.9%/month.
A17: Agent productivity | B17: =CHOOSE($C$6,C17,D17,E17) | C17: 6 | D17: 9 | E17: 3 | F17: accounts/agent/month | G17: RE-EVIDENCED 2026-08-26. Base HOLDS at 6; the BANDS widen from 8/3 to 9/3 and the justification is rebuilt on measured comparators instead of resting on a single insurance-agency analogy. WHAT THE EVIDENCE SAYS. IRDAI's Annual Report FY25 gives 270.22 lakh new individual policies against 31.23 lakh individual agents - 8.65 policies per agent per YEAR, or 0.72/month, across the whole book INCLUDING dormant agents. Adjusting for dormancy (MicroSave measures up to 43% inactive across the top four BC network managers) puts an ACTIVE Indian life agent at roughly 1.5-3 per month. BEWARE ONE WIDELY-CIRCULATED FIGURE: an analyst piece states Indian productivity as '0.87 policies per agent per year'. That is an ARITHMETIC SLIP - it divides 27.02 lakh by 31.23 lakh when the numerator is 270.22 lakh. The correct figure is 8.65. Do not cite the 0.87. THE CLOSER COMPARATOR IS THE BANK MITRA / BC NETWORK, which opens a light, form-based account for the same demographic through the same field model: 20-30 accounts per month when the account is FREE, and about 2 per month once a fee is introduced - a 93% collapse, measured by MicroSave. AURUMIX CHARGES 5% ON ENTRY. That is the datapoint arguing 6 is at the OPTIMISTIC end rather than the conservative one, and it is why the conservative band moves from 3 to... 3, but now for a stated reason rather than as a round number. THE OLD NOTE argued 6 was conservative because a gold SIP signup is a fraction of the work of an underwritten insurance policy. That is true, and it is why 6 survives as Base - but it argues only against the insurance figure and is silent on the fee-friction evidence, which points the other way. COMPOUNDS WITH HEADCOUNT: both are execution assumptions, and if either disappoints the other does not compensate. TRIANGULATED at 6, with the band now evidence-led in both directions.
A18: Marketing CAC - UAE | B18: =CHOOSE($C$6,C18,D18,E18) | C18: 85 | D18: 55 | E18: 140 | F18: USD per customer | G18: REGIONALISED 2026-08-20. A single global USD 120 was applied everywhere, which is roughly right for the UAE and badly wrong for India. PUBLISHED BENCHMARKS: Dubai consumer fintech USD 65-220; retail neobank account paid-only USD 35-70; GCC wealthtech funded accounts USD 80-220; 'true' fully-loaded CAC per ACTIVATED customer USD 85-350 against USD 50-100 reported, once KYC, onboarding and non-activating signups are counted. INDIA IS A DIFFERENT MARKET ENTIRELY: consumer fintech INR 500-1,500 (~USD 6-18), neobank savings activation INR 1,100-1,800, wealth and broking apps INR 2,500-5,500 (~USD 30-65); Jupiter reports a USD 5-6 paid CAC. USD 120 is ~INR 10,500 - some 7-20x the Indian mass-market benchmark and still 2-4x its premium wealth apps. UAE is held at 120 as a FULLY-LOADED figure; note it sits at the top of the range for a LOW-TICKET product, and the published low-ticket band is USD 4-70. TRIANGULATED. THIS IS THE YEAR-1 VALUE. CAC now ramps DOWN to the Y7 parameter below - see that note.
A19: Marketing CAC - Oman and Bahrain | B19: =CHOOSE($C$6,C19,D19,E19) | C19: 75 | D19: 50 | E19: 125 | F19: USD per customer | G19: REGIONALISED 2026-08-20. A single global USD 120 was applied everywhere, which is roughly right for the UAE and badly wrong for India. PUBLISHED BENCHMARKS: Dubai consumer fintech USD 65-220; retail neobank account paid-only USD 35-70; GCC wealthtech funded accounts USD 80-220; 'true' fully-loaded CAC per ACTIVATED customer USD 85-350 against USD 50-100 reported, once KYC, onboarding and non-activating signups are counted. INDIA IS A DIFFERENT MARKET ENTIRELY: consumer fintech INR 500-1,500 (~USD 6-18), neobank savings activation INR 1,100-1,800, wealth and broking apps INR 2,500-5,500 (~USD 30-65); Jupiter reports a USD 5-6 paid CAC. USD 120 is ~INR 10,500 - some 7-20x the Indian mass-market benchmark and still 2-4x its premium wealth apps. UAE is held at 120 as a FULLY-LOADED figure; note it sits at the top of the range for a LOW-TICKET product, and the published low-ticket band is USD 4-70. TRIANGULATED. THIS IS THE YEAR-1 VALUE. CAC now ramps DOWN to the Y7 parameter below - see that note.
A20: Marketing CAC - India | B20: =CHOOSE($C$6,C20,D20,E20) | C20: 15 | D20: 9 | E20: 26 | F20: USD per customer | G20: REGIONALISED 2026-08-20. A single global USD 120 was applied everywhere, which is roughly right for the UAE and badly wrong for India. PUBLISHED BENCHMARKS: Dubai consumer fintech USD 65-220; retail neobank account paid-only USD 35-70; GCC wealthtech funded accounts USD 80-220; 'true' fully-loaded CAC per ACTIVATED customer USD 85-350 against USD 50-100 reported, once KYC, onboarding and non-activating signups are counted. INDIA IS A DIFFERENT MARKET ENTIRELY: consumer fintech INR 500-1,500 (~USD 6-18), neobank savings activation INR 1,100-1,800, wealth and broking apps INR 2,500-5,500 (~USD 30-65); Jupiter reports a USD 5-6 paid CAC. USD 120 is ~INR 10,500 - some 7-20x the Indian mass-market benchmark and still 2-4x its premium wealth apps. UAE is held at 120 as a FULLY-LOADED figure; note it sits at the top of the range for a LOW-TICKET product, and the published low-ticket band is USD 4-70. TRIANGULATED. THIS IS THE YEAR-1 VALUE. CAC now ramps DOWN to the Y7 parameter below - see that note.
A21: Marketing CAC at Y7 - UAE | B21: =CHOOSE($C$6,C21,D21,E21) | C21: 55 | D21: 36 | E21: 91 | F21: USD per customer | G21: CLIENT INSTRUCTION 2026-08-26: CAC RAMPS DOWN over the horizon rather than sitting flat. UAE 85->55, Oman and Bahrain 75->45, India 15->10, interpolated LINEARLY on model year. Aggressive and Conservative hold the same proportional decline as Base. WHY IT FALLS: brand recognition compounds, organic and word-of-mouth grow off a larger base, and paid channels get cheaper per acquisition as creative, targeting and funnel conversion are tuned. IT CUTS AGAINST THE MODEL'S OWN CAUTION ELSEWHERE - S25's convexity switch says CAC RISES with spend because you buy progressively worse audiences. Both are real and they pull in opposite directions; this ramp asserts that the learning effect wins over seven years. IT IS NOT A COST SAVING - IT IS A REVENUE INCREASE. The marketing budget is fixed by schedule, so a lower CAC buys MORE CUSTOMERS for the same money. Marketing spend does not fall by a dollar.
A22: Marketing CAC at Y7 - Oman and Bahrain | B22: =CHOOSE($C$6,C22,D22,E22) | C22: 45 | D22: 30 | E22: 75 | F22: USD per customer | G22: CLIENT INSTRUCTION 2026-08-26: CAC RAMPS DOWN over the horizon rather than sitting flat. UAE 85->55, Oman and Bahrain 75->45, India 15->10, interpolated LINEARLY on model year. Aggressive and Conservative hold the same proportional decline as Base. WHY IT FALLS: brand recognition compounds, organic and word-of-mouth grow off a larger base, and paid channels get cheaper per acquisition as creative, targeting and funnel conversion are tuned. IT CUTS AGAINST THE MODEL'S OWN CAUTION ELSEWHERE - S25's convexity switch says CAC RISES with spend because you buy progressively worse audiences. Both are real and they pull in opposite directions; this ramp asserts that the learning effect wins over seven years. IT IS NOT A COST SAVING - IT IS A REVENUE INCREASE. The marketing budget is fixed by schedule, so a lower CAC buys MORE CUSTOMERS for the same money. Marketing spend does not fall by a dollar.
A23: Marketing CAC at Y7 - India | B23: =CHOOSE($C$6,C23,D23,E23) | C23: 10 | D23: 6 | E23: 17 | F23: USD per customer | G23: CLIENT INSTRUCTION 2026-08-26: CAC RAMPS DOWN over the horizon rather than sitting flat. UAE 85->55, Oman and Bahrain 75->45, India 15->10, interpolated LINEARLY on model year. Aggressive and Conservative hold the same proportional decline as Base. WHY IT FALLS: brand recognition compounds, organic and word-of-mouth grow off a larger base, and paid channels get cheaper per acquisition as creative, targeting and funnel conversion are tuned. IT CUTS AGAINST THE MODEL'S OWN CAUTION ELSEWHERE - S25's convexity switch says CAC RISES with spend because you buy progressively worse audiences. Both are real and they pull in opposite directions; this ramp asserts that the learning effect wins over seven years. IT IS NOT A COST SAVING - IT IS A REVENUE INCREASE. The marketing budget is fixed by schedule, so a lower CAC buys MORE CUSTOMERS for the same money. Marketing spend does not fall by a dollar.
A24: Marketing spend share - UAE | B24: =CHOOSE($C$6,C24,D24,E24) | C24: 0.74 | D24: 0.74 | E24: 0.74 | F24: % of budget | G24: RE-BASED 2026-08-26 from 58/16/26, when India moved to an agent-led channel. India falls to 8% - a SUPPORT budget, not an acquisition engine - and UAE and Oman & Bahrain absorb the residual, split roughly 80:20 by each region's share of its own reachable ceiling. THE REASON IS STRUCTURAL, NOT A PREFERENCE. UAE and Oman & Bahrain now have NO agent channel at all, so marketing plus referral is the WHOLE of their acquisition and the budget has to carry it. India's 420 agents carry ~57% of its new accounts by Y7, so its budget does not. WHAT THIS FIXES: holding India at 26% meant a USD 1.65m budget at a USD 15 CAC buying 35,750 accounts a year, which is what the model did before. India LOOKED agent-led while actually being carried by a cheap-CAC assumption - marketing was 67% of Indian raw demand at Y7 and agents only 11%, the reverse of how the business is described. Does not vary by scenario - it is a management decision, not an uncertainty. Must sum to 100%.
A25: Marketing spend share - Oman and Bahrain | B25: =CHOOSE($C$6,C25,D25,E25) | C25: 0.18 | D25: 0.18 | E25: 0.18 | F25: % of budget | G25: RE-BASED 2026-08-26 from 58/16/26, when India moved to an agent-led channel. India falls to 8% - a SUPPORT budget, not an acquisition engine - and UAE and Oman & Bahrain absorb the residual, split roughly 80:20 by each region's share of its own reachable ceiling. THE REASON IS STRUCTURAL, NOT A PREFERENCE. UAE and Oman & Bahrain now have NO agent channel at all, so marketing plus referral is the WHOLE of their acquisition and the budget has to carry it. India's 420 agents carry ~57% of its new accounts by Y7, so its budget does not. WHAT THIS FIXES: holding India at 26% meant a USD 1.65m budget at a USD 15 CAC buying 35,750 accounts a year, which is what the model did before. India LOOKED agent-led while actually being carried by a cheap-CAC assumption - marketing was 67% of Indian raw demand at Y7 and agents only 11%, the reverse of how the business is described. Does not vary by scenario - it is a management decision, not an uncertainty. Must sum to 100%.
A26: Marketing spend share - India | B26: =CHOOSE($C$6,C26,D26,E26) | C26: 0.08 | D26: 0.08 | E26: 0.08 | F26: % of budget | G26: RE-BASED 2026-08-26 from 58/16/26, when India moved to an agent-led channel. India falls to 8% - a SUPPORT budget, not an acquisition engine - and UAE and Oman & Bahrain absorb the residual, split roughly 80:20 by each region's share of its own reachable ceiling. THE REASON IS STRUCTURAL, NOT A PREFERENCE. UAE and Oman & Bahrain now have NO agent channel at all, so marketing plus referral is the WHOLE of their acquisition and the budget has to carry it. India's 420 agents carry ~57% of its new accounts by Y7, so its budget does not. WHAT THIS FIXES: holding India at 26% meant a USD 1.65m budget at a USD 15 CAC buying 35,750 accounts a year, which is what the model did before. India LOOKED agent-led while actually being carried by a cheap-CAC assumption - marketing was 67% of Indian raw demand at Y7 and agents only 11%, the reverse of how the business is described. Does not vary by scenario - it is a management decision, not an uncertainty. Must sum to 100%.
A27: Referral rate | B27: =CHOOSE($C$6,C27,D27,E27) | C27: 0.6 | D27: 1.1 | E27: 0.25 | F27: referrals/customer/yr | G27: RAISED 2026-08-21 from 0.45, client instruction. Cap removed deliberately, so the distribution is right-skewed - MODEL THE MEAN, NOT THE MEDIAN. 0.60 means the average customer produces roughly three referrals every five years; the mean is pulled up by a small number of highly social referrers, which is the normal shape for a trust-based product inside a tight diaspora community. IT IS STILL AN ASSUMPTION WITH NO EXTERNAL ANCHOR, and it compounds: referrals feed the paying base, which feeds more referrals. That loop is the reason this parameter is more load-bearing than its size suggests. ASSUMPTION.
A28: Referral conversion | B28: =CHOOSE($C$6,C28,D28,E28) | C28: 0.62 | D28: 0.72 | E28: 0.48 | F28: % | G28: The M7 survival of the referred cohort, uplifted ~1.1x. DERIVED.
... A30: Seasonality amplitude | B30: =CHOOSE($C$6,C30,D30,E30) | C30: 1 | D30: 1.4 | E30: 0.6 | F30: x deviation from 1.0 | G30: Festival TIMING is sourced; how hard a Dubai savings signup responds to Dhanteras is the open question. Applied to the deviation from 1.0, then renormalised, so the vectors stay at exactly 12.000.
A32: GROUP B: ICS BENEFIT ENTITLEMENT - no longer gates ACCESS, only BENEFITS
A33: Parameter | B33: Active Value | C33: Base | D33: Aggressive | E33: Conservative | F33: Unit
A34: Customers who EVER reach an ICS benefit tier | B34: =CHOOSE($C$6,C34,D34,E34) | C34: 0.55 | D34: 0.65 | E34: 0.45 | F34: % of customers | G34: REPURPOSED 2026-08-26 (CG decision). THIS CELL NO LONGER GATES ACCESS TO ANYTHING. The card and the credit facility are now open to the whole book regardless of SIP status or ICS tier; what ICS still governs is BENEFITS - fee discounts, better FX rates, family-wallet pricing, gold reward rebates. IT FEEDS NO REVENUE ROW TODAY. It is carried as a memo on the Model so the ICS-entitled population is already computed when the cost and discount build lands, because every one of those benefits is a give-back that has to be sized against a population. Deleting it would mean rebuilding it a day later. WHAT IT USED TO DO, AND WHY THE CHANGE IS LARGE: it restricted the card streams to the 55% who ever cleared a six-payment gate, so removing it widens the card population by 1/0.55 = 1.82x AND removes the ~8-month lag before anyone qualified. The old note called this 'the single most load-bearing parameter in the model' and claimed the card streams were ~83% of gross profit; BOTH STATEMENTS ARE NOW STALE - there is no gross-profit line in this build at all, and on the current numbers the card streams are a far smaller share of revenue than that. The 55% itself is unchanged and still the OUTPUT of the run-of-6 first-passage engine validated against the archetype mix, which now lives in the Phase 5 simulation. Whether ICS ENTITLEMENT should use the same threshold as the old payment gate is an OPEN QUESTION for the mechanism-design update - it is inherited here, not decided.
A35: Average months to reach an ICS benefit tier | B35: =CHOOSE($C$6,C35,D35,E35) | C35: 8 | D35: 6 | E35: 11 | F35: months | G35: REPURPOSED 2026-08-26 with the row above - it no longer delays card access, only benefit entitlement. Tier arrival is a DISTRIBUTION, not a date: a customer who misses month 4 cannot qualify before month 9. The validated mean is M8.0, against the naive assumption of M6. UNDER THE OLD DESIGN those two extra months pushed every card ladder date to the right and were worth real revenue; under the new one they delay only the point at which a customer starts COSTING money in discounts, which is the opposite sign. DERIVED.
A37: GROUP C: AUM, LEAKAGE AND SPOT
A38: Parameter | B38: Active Value | C38: Base | D38: Aggressive | E38: Conservative | F38: Unit
A39: Gold moved out of Aurumix's control | B39: =CHOOSE($C$6,C39,D39,E39) | C39: 0.06 | D39: 0.03 | E39: 0.18 | F39: % of AUM/yr | G39: HALVED 2026-08-21 from 0.12, client instruction. NOTE IT HAS ZERO EFFECT ON GOLD UNDER CUSTODY - measured, not asserted - because self-custodied metal never left the vault and was never in that measure. It moves ONLY the collateral-eligible base and therefore the card credit limit, worth ~0.2% of Y7 revenue. RELABELLED earlier the same day after the client correctly objected to the old name, 'self-custody leakage'. THE GOLD DOES NOT LEAVE THE VAULT: a token moving to a customer's own wallet sells nothing and burns nothing, so calling it an AUM decrease was wrong. What it does leave is Aurumix's COLLATERAL-ELIGIBLE base - Aurumix cannot foreclose on a token sitting in a private wallet, so that gold can no longer back a credit limit. In this model AUM has exactly ONE consumer, the card credit limit, so the arithmetic was always right and only the label was misleading. THAT ONE-CONSUMER PROPERTY IS WHAT MAKES THIS SAFE: if a later build points anything else at AUM - a custody fee, a reported-AUM headline - this row must be split in two first. Contrast the redemption line, which IS gold genuinely gone. ASSUMPTION.
A40: Redemption rate | B40: =CHOOSE($C$6,C40,D40,E40) | C40: 0.06 | D40: 0.035 | E40: 0.12 | F40: % of AUM/yr | G40: LOWERED 2026-08-21 from 0.08, client instruction - AND THIS ONE MOVES TOWARDS THE EVIDENCE, not away from it. PAXG turnover of 5.9% is the only comparator that exists, and 8% sat above it for no stated reason; 6% sits essentially on it. A DIFFERENT EVENT from gold moving out of Aurumix's control, and a separate line: this is metal actually sold and tokens burned. VARA forbids charging any fee on it. ASSUMPTION, now aligned to the single available comparator.
A41: Holder redemption multiplier | B41: =CHOOSE($C$6,C41,D41,E41) | C41: 1.6 | D41: 1.3 | E41: 2.8 | F41: x the paying rate | G41: LOWERED 2026-08-21 from 2.2, client instruction. THIS IS THE WEAKEST OF THE THREE DECAY CHANGES. The LOGIC behind a multiplier above 1.0 is untouched and still holds: customers who stopped paying redeem faster, because they have no accruing benefit left to protect. Lowering it to 1.6 weakens that argument without new evidence for the smaller number - it says lapsed customers are stickier than previously assumed, which is the convenient direction. Because holders become the majority of the book by Y4, this remains the DOMINANT AUM DECAY TERM from roughly Y4, so the change is not cosmetic. ASSUMPTION, and the first one to revisit if AUM is challenged.
A42: Spot attach scenario multiplier | B42: =CHOOSE($C$6,C42,D42,E42) | C42: 1 | D42: 1.7 | E42: 0.5 | F42: x the regional attach | G42: REGIONALISED 2026-08-21. The attach LEVEL now sits per region on Assumptions (UAE 12%, Oman & Bahrain 10%, India 25%); this dial carries only the uncertainty around it, preserving the old 14/24/7 spread (1.00 / 1.70 / 0.50). ONE DIAL, NOT THREE TRIPLETS - nine numbers to defend, and a scenario could otherwise silently invert the regional ordering that affordability establishes. See the regional rows on Assumptions for the reasoning. ASSUMPTION about spread.
A43: Spot ticket scenario multiplier | B43: =CHOOSE($C$6,C43,D43,E43) | C43: 1 | D43: 1.35 | E43: 0.7 | F43: x the observed ticket | G43: REPLACED the global 'Average spot ticket' on 2026-08-21. The LEVEL is no longer a scenario input: each region now carries its own OBSERVED ticket on Assumptions (UAE 190 from Botim, India 40 from Augmont, Oman & Bahrain 145 inferred). This parameter carries only the UNCERTAINTY around those observations, as a single dial. WHY ONE DIAL AND NOT THREE: three regional triplets would be nine numbers to defend and would let a scenario silently invert the regional ordering that the sources establish. One multiplier flexes the level and PRESERVES the ordering. Aggressive 1.35 puts the UAE at ~257, still under the AED 1,000 mark; conservative 0.70 puts it at ~133, below Botim's own sub-AED-500 majority. ASSUMPTION about spread, applied to observed levels.
A44: Spot frequency | B44: =CHOOSE($C$6,C44,D44,E44) | C44: 1.7 | D44: 2.4 | E44: 1.2 | F44: events/attacher/yr | G44: PROVENANCE CORRECTED 2026-08-21 - THE NUMBER STANDS, ITS OLD CITATION DID NOT. The previous note read 'Botim's 128,000 trades against ~45,000 buyers implies ~1.9/yr'. THE 45,000 IS NOT A BUYER COUNT, IT IS A TRANSACTION COUNT: Khaleej Times, Nov 2025, says 775,000 users EXPLORED the feature, 'completing over 45,000 transactions'. The 128,000 is also transactions, to Feb 2026. So the old derivation divided transactions by transactions across two different windows - the result was the growth in cumulative trades, not a frequency. CONFIRMED NEGATIVE: Botim has never published a unique-buyer count, so no frequency can be derived from it, and no published frequency exists ANYWHERE for ad-hoc lump gold purchases. Comparators are 0.85/yr (Augmont, per REGISTERED user, at an average transaction of Rs 331 - micro-saving, not lumps) and 264/yr (Jar, Rs 10/day auto-roundups) - a 300x spread, neither being this product. WHAT DOES SUPPORT 1.7 is a cross-check on the COMBINED basis, attach x frequency x ticket, which is comparable: Aurumix India implies ~Rs 838/yr of gold per paying customer against Augmont's ~Rs 281/yr per registered user. 3x, and defensible - our customers are engaged SIP savers, not dormant registrations. Behaviourally 1.7 is also about right for festive lumps: Dhanteras, Akshaya Tritiya and a wedding is roughly two events. ASSUMPTION, cross-checked on the combined basis, NOT directly sourced.
A46: GROUP D: CARD
A47: Parameter | B47: Active Value | C47: Base | D47: Aggressive | E47: Conservative | F47: Unit
A48: Programme manager share of interchange | B48: =CHOOSE($C$6,C48,D48,E48) | C48: 0.6 | D48: 0.36 | E48: 0.85 | F48: % | G48: LOWERED 2026-08-21 from 0.72, client instruction - AURUMIX NOW KEEPS 40% RATHER THAN 28%. 0.60 sits comfortably inside the 36-85% observed range and is roughly its midpoint, so the base case moves from the pessimistic end to a neutral one. It assumes a NEGOTIATED deal rather than a take-it-or-leave-it one, which is reasonable for a programme with a gold-collateral proposition the manager cannot source elsewhere - but it IS an assumption about a contract that does not exist yet, and the only honest way to hold it is to treat 40% as a target to negotiate to, not a rate already won. BANDS CORRECTED earlier the same day - THEY WERE INVERTED. Aggressive was 0.85 and conservative 0.55, meaning the OPTIMISTIC scenario handed MORE of the interchange to the programme manager and cut Aurumix's share from 28% to 15%. Every other cost-like parameter in this model improves under Aggressive - redemption, CAC, self-custody, the holder multiplier - and this one moved the other way. Flipping the scenario made interchange fall 46% in the good case and rise 61% in the bad one. Aggressive is now 0.36, THE DOCUMENTED FLOOR, which is the best deal observed anywhere and the right walk-away to take into a sponsor conversation - at that level Aurumix keeps 64% rather than 28%, and interchange more than doubles. Conservative is 0.85. WHY AURUMIX ONLY GETS A SLICE AT ALL: it is not a bank and cannot issue cards, so a programme manager holds the BIN, the scheme membership, settlement and dispute handling, and takes the majority for it. That much is normal. 72% is near the BAD END of the 36-85% range, so the base case is deliberately unfavourable - THIS IS A COMMERCIAL NEGOTIATION, NOT A MODELLING ASSUMPTION, and it is one of the few places where a better contract directly doubles a revenue line. No UAE/MENA figure is published. TRIANGULATED.
...

Sheet Model
A1: =Cover!$B$2
A2: Period # | B2: 1..29 | C2: 1 | D2: 2 | E2: 3 | F2: 4 | G2: 5 | H2: 6 | I2: 7 | J2: 8 | K2: 9 | L2: 10 | M2: 11 | N2: 12 | O2: 13 | P2: 14 | Q2: 15 | R2: 16 | S2: 17 | T2: 18 | U2: 19 | V2: 20 | W2: 21 | X2: 22 | Y2: 23 | Z2: 24 | AA2: 25 | AB2: 26 | AC2: 27 | AD2: 28 | AE2: 29
A3: Period | B3: - | C3: M1 | D3: M2 | E3: M3 | F3: M4 | G3: M5 | H3: M6 | I3: M7 | J3: M8 | K3: M9 | L3: M10 | M3: M11 | N3: M12 | O3: M13 | P3: M14 | Q3: M15 | R3: M16 | S3: M17 | T3: M18 | U3: M19 | V3: M20 | W3: M21 | X3: M22 | Y3: M23 | Z3: M24 | AA3: Y3 | AB3: Y4 | AC3: Y5 | AD3: Y6 | AE3: Y7
A4: Period type | B4: - | C4: Monthly | D4: Monthly | E4: Monthly | F4: Monthly | G4: Monthly | H4: Monthly | I4: Monthly | J4: Monthly | K4: Monthly | L4: Monthly | M4: Monthly | N4: Monthly | O4: Monthly | P4: Monthly | Q4: Monthly | R4: Monthly | S4: Monthly | T4: Monthly | U4: Monthly | V4: Monthly | W4: Monthly | X4: Monthly | Y4: Monthly | Z4: Monthly | AA4: Annual | AB4: Annual | AC4: Annual | AD4: Annual | AE4: Annual
A5: Model year | B5: 1..7 | C5: 1 | D5: 1 | E5: 1 | F5: 1 | G5: 1 | H5: 1 | I5: 1 | J5: 1 | K5: 1 | L5: 1 | M5: 1 | N5: 1 | O5: 2 | P5: 2 | Q5: 2 | R5: 2 | S5: 2 | T5: 2 | U5: 2 | V5: 2 | W5: 2 | X5: 2 | Y5: 2 | Z5: 2 | AA5: 3 | AB5: 4 | AC5: 5 | AD5: 6 | AE5: 7
A6: Calendar month | B6: 0 = annual | C6: 1 | D6: 2 | E6: 3 | F6: 4 | G6: 5 | H6: 6 | I6: 7 | J6: 8 | K6: 9 | L6: 10 | M6: 11 | N6: 12 | O6: 1 | P6: 2 | Q6: 3 | R6: 4 | S6: 5 | T6: 6 | U6: 7 | V6: 8 | W6: 9 | X6: 10 | Y6: 11 | Z6: 12 | AA6: 0 | AB6: 0 | AC6: 0 | AD6: 0 | AE6: 0
A7: Months in period | B7: months | C7: 1 | D7: 1 | E7: 1 | F7: 1 | G7: 1 | H7: 1 | I7: 1 | J7: 1 | K7: 1 | L7: 1 | M7: 1 | N7: 1 | O7: 1 | P7: 1 | Q7: 1 | R7: 1 | S7: 1 | T7: 1 | U7: 1 | V7: 1 | W7: 1 | X7: 1 | Y7: 1 | Z7: 1 | AA7: 12 | AB7: 12 | AC7: 12 | AD7: 12 | AE7: 12
A8: Financial-year end | B8: 1/0 | C8: 0 | D8: 0 | E8: 0 | F8: 0 | G8: 0 | H8: 0 | I8: 0 | J8: 0 | K8: 0 | L8: 0 | M8: 0 | N8: 1 | O8: 0 | P8: 0 | Q8: 0 | R8: 0 | S8: 0 | T8: 0 | U8: 0 | V8: 0 | W8: 0 | X8: 0 | Y8: 0 | Z8: 1 | AA8: 1 | AB8: 1 | AC8: 1 | AD8: 1 | AE8: 1
A10: SEASONALITY - normalised to EXACTLY 12.000 by construction
A11: Acquisition seasonality - normalised | B11: Jan..Dec | C11: =(1+(Assumptions!$F$61-1)*Assumptions!$B$148)*12/SUMPRODUCT(1+(Assumptions!$F$61:$Q$61-1)*Assumptions!$B$148) | D11: =(1+(Assumptions!$G$61-1)*Assumptions!$B$148)*12/SUMPRODUCT(1+(Assumptions!$F$61:$Q$61-1)*Assumptions!$B$148) | E11: =(1+(Assumptions!$H$61-1)*Assumptions!$B$148)*12/SUMPRODUCT(1+(Assumptions!$F$61:$Q$61-1)*Assumptions!$B$148) | F11: =(1+(Assumptions!$I$61-1)*Assumptions!$B$148)*12/SUMPRODUCT(1+(Assumptions!$F$61:$Q$61-1)*Assumptions!$B$148) | G11: =(1+(Assumptions!$J$61-1)*Assumptions!$B$148)*12/SUMPRODUCT(1+(Assumptions!$F$61:$Q$61-1)*Assumptions!$B$148) | H11: =(1+(Assumptions!$K$61-1)*Assumptions!$B$148)*12/SUMPRODUCT(1+(Assumptions!$F$61:$Q$61-1)*Assumptions!$B$148) | I11: =(1+(Assumptions!$L$61-1)*Assumptions!$B$148)*12/SUMPRODUCT(1+(Assumptions!$F$61:$Q$61-1)*Assumptions!$B$148) | J11: =(1+(Assumptions!$M$61-1)*Assumptions!$B$148)*12/SUMPRODUCT(1+(Assumptions!$F$61:$Q$61-1)*Assumptions!$B$148) | K11: =(1+(Assumptions!$N$61-1)*Assumptions!$B$148)*12/SUMPRODUCT(1+(Assumptions!$F$61:$Q$61-1)*Assumptions!$B$148) | L11: =(1+(Assumptions!$O$61-1)*Assumptions!$B$148)*12/SUMPRODUCT(1+(Assumptions!$F$61:$Q$61-1)*Assumptions!$B$148) | M11: =(1+(Assumptions!$P$61-1)*Assumptions!$B$148)*12/SUMPRODUCT(1+(Assumptions!$F$61:$Q$61-1)*Assumptions!$B$148) | N11: =(1+(Assumptions!$Q$61-1)*Assumptions!$B$148)*12/SUMPRODUCT(1+(Assumptions!$F$61:$Q$61-1)*Assumptions!$B$148)
A12: Card spend seasonality - normalised | B12: Jan..Dec | C12: =(1+(Assumptions!$F$62-1)*Assumptions!$B$148)*12/SUMPRODUCT(1+(Assumptions!$F$62:$Q$62-1)*Assumptions!$B$148) | D12: =(1+(Assumptions!$G$62-1)*Assumptions!$B$148)*12/SUMPRODUCT(1+(Assumptions!$F$62:$Q$62-1)*Assumptions!$B$148) | E12: =(1+(Assumptions!$H$62-1)*Assumptions!$B$148)*12/SUMPRODUCT(1+(Assumptions!$F$62:$Q$62-1)*Assumptions!$B$148) | F12: =(1+(Assumptions!$I$62-1)*Assumptions!$B$148)*12/SUMPRODUCT(1+(Assumptions!$F$62:$Q$62-1)*Assumptions!$B$148) | G12: =(1+(Assumptions!$J$62-1)*Assumptions!$B$148)*12/SUMPRODUCT(1+(Assumptions!$F$62:$Q$62-1)*Assumptions!$B$148) | H12: =(1+(Assumptions!$K$62-1)*Assumptions!$B$148)*12/SUMPRODUCT(1+(Assumptions!$F$62:$Q$62-1)*Assumptions!$B$148) | I12: =(1+(Assumptions!$L$62-1)*Assumptions!$B$148)*12/SUMPRODUCT(1+(Assumptions!$F$62:$Q$62-1)*Assumptions!$B$148) | J12: =(1+(Assumptions!$M$62-1)*Assumptions!$B$148)*12/SUMPRODUCT(1+(Assumptions!$F$62:$Q$62-1)*Assumptions!$B$148) | K12: =(1+(Assumptions!$N$62-1)*Assumptions!$B$148)*12/SUMPRODUCT(1+(Assumptions!$F$62:$Q$62-1)*Assumptions!$B$148) | L12: =(1+(Assumptions!$O$62-1)*Assumptions!$B$148)*12/SUMPRODUCT(1+(Assumptions!$F$62:$Q$62-1)*Assumptions!$B$148) | M12: =(1+(Assumptions!$P$62-1)*Assumptions!$B$148)*12/SUMPRODUCT(1+(Assumptions!$F$62:$Q$62-1)*Assumptions!$B$148) | N12: =(1+(Assumptions!$Q$62-1)*Assumptions!$B$148)*12/SUMPRODUCT(1+(Assumptions!$F$62:$Q$62-1)*Assumptions!$B$148)
A13: Foreign-spend share - rescaled to the mean | B13: Jan..Dec | C13: =Assumptions!$F$63/AVERAGE(Assumptions!$F$63:$Q$63)*Assumptions!$B$160 | D13: =Assumptions!$G$63/AVERAGE(Assumptions!$F$63:$Q$63)*Assumptions!$B$160 | E13: =Assumptions!$H$63/AVERAGE(Assumptions!$F$63:$Q$63)*Assumptions!$B$160 | F13: =Assumptions!$I$63/AVERAGE(Assumptions!$F$63:$Q$63)*Assumptions!$B$160 | G13: =Assumptions!$J$63/AVERAGE(Assumptions!$F$63:$Q$63)*Assumptions!$B$160 | H13: =Assumptions!$K$63/AVERAGE(Assumptions!$F$63:$Q$63)*Assumptions!$B$160 | I13: =Assumptions!$L$63/AVERAGE(Assumptions!$F$63:$Q$63)*Assumptions!$B$160 | J13: =Assumptions!$M$63/AVERAGE(Assumptions!$F$63:$Q$63)*Assumptions!$B$160 | K13: =Assumptions!$N$63/AVERAGE(Assumptions!$F$63:$Q$63)*Assumptions!$B$160 | L13: =Assumptions!$O$63/AVERAGE(Assumptions!$F$63:$Q$63)*Assumptions!$B$160 | M13: =Assumptions!$P$63/AVERAGE(Assumptions!$F$63:$Q$63)*Assumptions!$B$160 | N13: =Assumptions!$Q$63/AVERAGE(Assumptions!$F$63:$Q$63)*Assumptions!$B$160
A14: Seasonality sum check (must be exactly 12.000) | B14: acq | spend | C14: =SUM($C$11:$N$11) | D14: =SUM($C$12:$N$12)
A15: Acquisition seasonality applied | B15: multiplier | C15: =IF(C7=1,INDEX($C$11:$N$11,1,C6),1) | D15: =IF(D7=1,INDEX($C$11:$N$11,1,D6),1) | E15: =IF(E7=1,INDEX($C$11:$N$11,1,E6),1) | F15: =IF(F7=1,INDEX($C$11:$N$11,1,F6),1) | G15: =IF(G7=1,INDEX($C$11:$N$11,1,G6),1) | H15: =IF(H7=1,INDEX($C$11:$N$11,1,H6),1) | I15: =IF(I7=1,INDEX($C$11:$N$11,1,I6),1) | J15: =IF(J7=1,INDEX($C$11:$N$11,1,J6),1) | ... AE15: =IF(AE7=1,INDEX($C$11:$N$11,1,AE6),1)
A16: Card spend seasonality applied | B16: multiplier | C16: =IF(C7=1,INDEX($C$12:$N$12,1,C6),1) | D16: =IF(D7=1,INDEX($C$12:$N$12,1,D6),1) | E16: =IF(E7=1,INDEX($C$12:$N$12,1,E6),1) | F16: =IF(F7=1,INDEX($C$12:$N$12,1,F6),1) | G16: =IF(G7=1,INDEX($C$12:$N$12,1,G6),1) | H16: =IF(H7=1,INDEX($C$12:$N$12,1,H6),1) | I16: =IF(I7=1,INDEX($C$12:$N$12,1,I6),1) | J16: =IF(J7=1,INDEX($C$12:$N$12,1,J6),1) | ... AE16: =IF(AE7=1,INDEX($C$12:$N$12,1,AE6),1)
A17: Foreign-spend share applied | B17: % | C17: =IF(C7=1,INDEX($C$13:$N$13,1,C6),AVERAGE($C$13:$N$13)) | D17: =IF(D7=1,INDEX($C$13:$N$13,1,D6),AVERAGE($C$13:$N$13)) | E17: =IF(E7=1,INDEX($C$13:$N$13,1,E6),AVERAGE($C$13:$N$13)) | F17: =IF(F7=1,INDEX($C$13:$N$13,1,F6),AVERAGE($C$13:$N$13)) | G17: =IF(G7=1,INDEX($C$13:$N$13,1,G6),AVERAGE($C$13:$N$13)) | H17: =IF(H7=1,INDEX($C$13:$N$13,1,H6),AVERAGE($C$13:$N$13)) | I17: =IF(I7=1,INDEX($C$13:$N$13,1,I6),AVERAGE($C$13:$N$13)) | J17: =IF(J7=1,INDEX($C$13:$N$13,1,J6),AVERAGE($C$13:$N$13)) | ... AE17: =IF(AE7=1,INDEX($C$13:$N$13,1,AE6),AVERAGE($C$13:$N$13))
A19: ACQUISITION - all channels, then split across regions
A20: Gold price (this period) | B20: USD/g | C20: =Assumptions!$B$6*(1+Assumptions!$B$131)^(C5-1) | D20: =Assumptions!$B$6*(1+Assumptions!$B$131)^(D5-1) | E20: =Assumptions!$B$6*(1+Assumptions!$B$131)^(E5-1) | F20: =Assumptions!$B$6*(1+Assumptions!$B$131)^(F5-1) | G20: =Assumptions!$B$6*(1+Assumptions!$B$131)^(G5-1) | H20: =Assumptions!$B$6*(1+Assumptions!$B$131)^(H5-1) | I20: =Assumptions!$B$6*(1+Assumptions!$B$131)^(I5-1) | J20: =Assumptions!$B$6*(1+Assumptions!$B$131)^(J5-1) | ... AE20: =Assumptions!$B$6*(1+Assumptions!$B$131)^(AE5-1)
A21: RISING GOLD CUTS BOTH WAYS AND THE MODEL CAPTURES BOTH. Metal already held appreciates, but a fixed USD contribution BUYS FEWER GRAMS each year - so AUM does NOT simply compound at the headline rate. Only the collateral-linked streams move with this row (card limit, and lending through it); the entry fee is a percentage of a USD contribution and is untouched by the gold price.
A22: REVENUE - the customer engine and the six streams, by region
A24: REGION: UAE
A25: Marketing CAC this period (ramping Y1 to Y7) | B25: USD/customer | C25: =Assumptions!$B$136+(Assumptions!$B$139-Assumptions!$B$136)*(C5-1)/6 | D25: =Assumptions!$B$136+(Assumptions!$B$139-Assumptions!$B$136)*(D5-1)/6 | E25: =Assumptions!$B$136+(Assumptions!$B$139-Assumptions!$B$136)*(E5-1)/6 | F25: =Assumptions!$B$136+(Assumptions!$B$139-Assumptions!$B$136)*(F5-1)/6 | G25: =Assumptions!$B$136+(Assumptions!$B$139-Assumptions!$B$136)*(G5-1)/6 | H25: =Assumptions!$B$136+(Assumptions!$B$139-Assumptions!$B$136)*(H5-1)/6 | I25: =Assumptions!$B$136+(Assumptions!$B$139-Assumptions!$B$136)*(I5-1)/6 | J25: =Assumptions!$B$136+(Assumptions!$B$139-Assumptions!$B$136)*(J5-1)/6 | ... AE25: =Assumptions!$B$136+(Assumptions!$B$139-Assumptions!$B$136)*(AE5-1)/6
A26: Direct-driven (this market's budget at its own CAC) | B26: accounts | C26: =INDEX(Assumptions!$B$114:$B$120,C5)*Assumptions!$B$142/12*C7/C25*(1+Assumptions!$B$147)*1 | D26: =INDEX(Assumptions!$B$114:$B$120,D5)*Assumptions!$B$142/12*D7/D25*(1+Assumptions!$B$147)*1 | E26: =INDEX(Assumptions!$B$114:$B$120,E5)*Assumptions!$B$142/12*E7/E25*(1+Assumptions!$B$147)*1 | F26: =INDEX(Assumptions!$B$114:$B$120,F5)*Assumptions!$B$142/12*F7/F25*(1+Assumptions!$B$147)*1 | G26: =INDEX(Assumptions!$B$114:$B$120,G5)*Assumptions!$B$142/12*G7/G25*(1+Assumptions!$B$147)*1 | H26: =INDEX(Assumptions!$B$114:$B$120,H5)*Assumptions!$B$142/12*H7/H25*(1+Assumptions!$B$147)*1 | I26: =INDEX(Assumptions!$B$114:$B$120,I5)*Assumptions!$B$142/12*I7/I25*(1+Assumptions!$B$147)*1 | J26: =INDEX(Assumptions!$B$114:$B$120,J5)*Assumptions!$B$142/12*J7/J25*(1+Assumptions!$B$147)*1 | ... AE26: =INDEX(Assumptions!$B$114:$B$120,AE5)*Assumptions!$B$142/12*AE7/AE25*(1+Assumptions!$B$147)*1
A27: Referral-driven (from this market's own base) | B27: accounts | C27: 0 | D27: =IF(D2>=Assumptions!$B$55,C32*Assumptions!$B$145/12*Assumptions!$B$146*D7,0) | E27: =IF(E2>=Assumptions!$B$55,D32*Assumptions!$B$145/12*Assumptions!$B$146*E7,0) | F27: =IF(F2>=Assumptions!$B$55,E32*Assumptions!$B$145/12*Assumptions!$B$146*F7,0) | G27: =IF(G2>=Assumptions!$B$55,F32*Assumptions!$B$145/12*Assumptions!$B$146*G7,0) | H27: =IF(H2>=Assumptions!$B$55,G32*Assumptions!$B$145/12*Assumptions!$B$146*H7,0) | I27: =IF(I2>=Assumptions!$B$55,H32*Assumptions!$B$145/12*Assumptions!$B$146*I7,0) | J27: =IF(J2>=Assumptions!$B$55,I32*Assumptions!$B$145/12*Assumptions!$B$146*J7,0) | K27: =IF(K2>=Assumptions!$B$55,J32*Assumptions!$B$145/12*Assumptions!$B$146*K7,0) | ... AE27: =IF(AE2>=Assumptions!$B$55,AD32*Assumptions!$B$145/12*Assumptions!$B$146*AE7,0)
A28: Agent-driven (this market's own agents) | B28: accounts | C28: =INDEX(Assumptions!$B$93:$B$99,C5)*Assumptions!$B$135*INDEX(Assumptions!$B$121:$B$127,C5)*C7*1 | D28: =INDEX(Assumptions!$B$93:$B$99,D5)*Assumptions!$B$135*INDEX(Assumptions!$B$121:$B$127,D5)*D7*1 | E28: =INDEX(Assumptions!$B$93:$B$99,E5)*Assumptions!$B$135*INDEX(Assumptions!$B$121:$B$127,E5)*E7*1 | F28: =INDEX(Assumptions!$B$93:$B$99,F5)*Assumptions!$B$135*INDEX(Assumptions!$B$121:$B$127,F5)*F7*1 | G28: =INDEX(Assumptions!$B$93:$B$99,G5)*Assumptions!$B$135*INDEX(Assumptions!$B$121:$B$127,G5)*G7*1 | H28: =INDEX(Assumptions!$B$93:$B$99,H5)*Assumptions!$B$135*INDEX(Assumptions!$B$121:$B$127,H5)*H7*1 | I28: =INDEX(Assumptions!$B$93:$B$99,I5)*Assumptions!$B$135*INDEX(Assumptions!$B$121:$B$127,I5)*I7*1 | J28: =INDEX(Assumptions!$B$93:$B$99,J5)*Assumptions!$B$135*INDEX(Assumptions!$B$121:$B$127,J5)*J7*1 | ... AE28: =INDEX(Assumptions!$B$93:$B$99,AE5)*Assumptions!$B$135*INDEX(Assumptions!$B$121:$B$127,AE5)*AE7*1
A29: Raw demand | B29: accounts | C29: =C26+C27+C28 | D29: =D26+D27+D28 | E29: =E26+E27+E28 | F29: =F26+F27+F28 | G29: =G26+G27+G28 | H29: =H26+H27+H28 | I29: =I26+I27+I28 | J29: =J26+J27+J28 | ... AE29: =AE26+AE27+AE28
A30: Saturation (this region's own headroom) | B30: x | C30: 1 | D30: =MAX(0,1-C35/Assumptions!$B$84) | E30: =MAX(0,1-D35/Assumptions!$B$84) | F30: =MAX(0,1-E35/Assumptions!$B$84) | G30: =MAX(0,1-F35/Assumptions!$B$84) | H30: =MAX(0,1-G35/Assumptions!$B$84) | I30: =MAX(0,1-H35/Assumptions!$B$84) | J30: =MAX(0,1-I35/Assumptions!$B$84) | K30: =MAX(0,1-J35/Assumptions!$B$84) | ... AE30: =MAX(0,1-AD35/Assumptions!$B$84)
A31: New customers | B31: accounts | C31: =C29*C30*C15 | D31: =D29*D30*D15 | E31: =E29*E30*E15 | F31: =F29*F30*F15 | G31: =G29*G30*G15 | H31: =H29*H30*H15 | I31: =I29*I30*I15 | J31: =J29*J30*J15 | ... AE31: =AE29*AE30*AE15
A32: Paying customers | B32: accounts | C32: =C31*(1-Assumptions!$B$134)^(C7/2) | D32: =C32*(1-Assumptions!$B$134)^D7+D31*(1-Assumptions!$B$134)^(D7/2) | E32: =D32*(1-Assumptions!$B$134)^E7+E31*(1-Assumptions!$B$134)^(E7/2) | F32: =E32*(1-Assumptions!$B$134)^F7+F31*(1-Assumptions!$B$134)^(F7/2) | G32: =F32*(1-Assumptions!$B$134)^G7+G31*(1-Assumptions!$B$134)^(G7/2) | H32: =G32*(1-Assumptions!$B$134)^H7+H31*(1-Assumptions!$B$134)^(H7/2) | I32: =H32*(1-Assumptions!$B$134)^I7+I31*(1-Assumptions!$B$134)^(I7/2) | J32: =I32*(1-Assumptions!$B$134)^J7+J31*(1-Assumptions!$B$134)^(J7/2) | K32: =J32*(1-Assumptions!$B$134)^K7+K31*(1-Assumptions!$B$134)^(K7/2) | ... AE32: =AD32*(1-Assumptions!$B$134)^AE7+AE31*(1-Assumptions!$B$134)^(AE7/2)
A33: Churned this period | B33: accounts | C33: =C31-C32 | D33: =C32+D31-D32 | E33: =D32+E31-E32 | F33: =E32+F31-F32 | G33: =F32+G31-G32 | H33: =G32+H31-H32 | I33: =H32+I31-I32 | J33: =I32+J31-J32 | K33: =J32+K31-K32 | ... AE33: =AD32+AE31-AE32
A34: Holders (stopped paying, still hold gold) | B34: accounts | C34: =C33 | D34: =C34+D33 | E34: =D34+E33 | F34: =E34+F33 | G34: =F34+G33 | H34: =G34+H33 | I34: =H34+I33 | J34: =I34+J33 | K34: =J34+K33 | ... AE34: =AD34+AE33
A35: Cumulative ever acquired | B35: accounts | C35: =C31 | D35: =C35+D31 | E35: =D35+E31 | F35: =E35+F31 | G35: =F35+G31 | H35: =G35+H31 | I35: =H35+I31 | J35: =I35+J31 | K35: =J35+K31 | ... AE35: =AD35+AE31
A36: SIP contributions | B36: USD | C36: =IF(C2>=Assumptions!$B$47,C32*Assumptions!$B$190*C7,0) | D36: =IF(D2>=Assumptions!$B$47,D32*Assumptions!$B$190*D7,0) | E36: =IF(E2>=Assumptions!$B$47,E32*Assumptions!$B$190*E7,0) | F36: =IF(F2>=Assumptions!$B$47,F32*Assumptions!$B$190*F7,0) | G36: =IF(G2>=Assumptions!$B$47,G32*Assumptions!$B$190*G7,0) | H36: =IF(H2>=Assumptions!$B$47,H32*Assumptions!$B$190*H7,0) | I36: =IF(I2>=Assumptions!$B$47,I32*Assumptions!$B$190*I7,0) | J36: =IF(J2>=Assumptions!$B$47,J32*Assumptions!$B$190*J7,0) | ... AE36: =IF(AE2>=Assumptions!$B$47,AE32*Assumptions!$B$190*AE7,0)
